<?xml version="1.0"?>
<robot name = "youbot" xmlns:xacro="http://www.ros.org/wiki/xacro">

<!--***************************************** WHEELED BASE ******************************************-->
  <link name = "chassis">
		<inertial>
			<mass value = "20"/>
			<origin xyz = "0 0 0.1" rpy = "0 0 0"/>
			<inertia ixx = "0.5933" ixy = "0" ixz = "0" iyy = "0.7963" iyz = "0" izz = "0.2683"/>
		</inertial>
		<collision>
			<geometry>
					<box  size = "0.580 0.376 0.140"/>
			</geometry>
		</collision>
		<visual>
			<geometry>
					<box  size = "0.580 0.376 0.140"/>
			</geometry>
		</visual>
	</link>
	
<!--join wheels with the chassis-->
	
  <joint name = "chassis__wheel_fl" type = "revolute">
		<origin xyz = "0.270 -0.200 0" rpy = "0 0 0"/>		
		<axis xyz= "0 1 0"/>
		<parent link = "chassis"/>
		<child link = "wheel_fl"/>
		<limit effort = "1" velocity = "1" lower = "-3.14" upper = "3.14"/>
		<dynamics damping="1.0" friction="0.3"/>
	</joint>
	<transmission name="chassis_wheel_fl_trans">
    <type>transmission_interface/SimpleTransmission</type>
    <actuator name="chassis_wheel_fl_act">
      <mechanicalReduction>1</mechanicalReduction>
    </actuator>
    <joint name="chassis_wheel_fl">
      <hardwareInterface>hardware_interface/EffortJointInterface</hardwareInterface>
    </joint>
  </transmission>
  <gazebo reference="wheel_fl">
      <mu1 value="200.0"/>
      <mu2 value="100.0"/>
      <kp value="10000000.0" />
      <kd value="1.0" />
      <material>Gazebo/Grey</material>
  </gazebo>

	
	
	<link name = "wheel_fl">
		<inertial>
			<mass value = "2"/>
			<origin xyz = "0 0 0" rpy = "1.57 0 0"/>
			<inertia ixx = "0.0022" ixy = "0" ixz = "0" iyy = "0.0022" iyz = "0" izz = "0.0025"/>
		</inertial>
		<collision>
			<origin xyz = "0 0 0" rpy = "1.57 0 0"/>
			<geometry>
					<cylinder  radius = "0.05" length = "0.076"/>
			</geometry>
		</collision>
		<visual>
			<origin xyz = "0 0 0" rpy = "1.57 0 0"/>
			<geometry>
					<cylinder  radius = "0.1" length = "0.076"/>
			</geometry>
		</visual>
	</link>
	
<!--join wheels with the base link-->

	<joint name = "chassis__wheel_fr" type = "revolute">
		<origin xyz = "0.270 0.200 0" rpy = "0 0 0"/>		
		<axis xyz= "0 1 0"/>
		<parent link = "chassis"/>
		<child link = "wheel_fr"/>
		<limit effort = "1" velocity = "1" lower = "-3.14" upper = "3.14"/>
    <dynamics damping="1.0" friction="0.3"/>
	</joint>
	<transmission name="chassis_wheel_fr_trans">
    <type>transmission_interface/SimpleTransmission</type>
    <actuator name="chassis_wheel_fr_act">
      <mechanicalReduction>1</mechanicalReduction>
    </actuator>
    <joint name="chassis_wheel_fr">
      <hardwareInterface>hardware_interface/EffortJointInterface</hardwareInterface>
    </joint>
  </transmission>
  <gazebo reference="wheel_fl">
      <mu1 value="200.0"/>
      <mu2 value="100.0"/>
      <kp value="10000000.0" />
      <kd value="1.0" />
      <material>Gazebo/Grey</material>
  </gazebo>
	
	<link name = "wheel_fr">
		<inertial>
			<mass value = "2"/>
			<origin xyz = "0 0 0" rpy = "1.57 0 0"/>
			<inertia ixx = "0.0022" ixy = "0" ixz = "0" iyy = "0.0022" iyz = "0" izz = "0.0025"/>
		</inertial>
		<collision>
			<origin xyz = "0 0 0" rpy = "1.57 0 0"/>
			<geometry>
					<cylinder  radius = "0.05" length = "0.076"/>
			</geometry>
		</collision>
		<visual>
			<origin xyz = "0 0 0" rpy = "1.57 0 0"/>
			<geometry>
					<cylinder  radius = "0.1" length = "0.076"/>
			</geometry>
		</visual>
	</link>

<!--join wheels with the base link-->

	<joint name = "chassis__wheel_rl" type = "revolute">
		<origin xyz = "-0.270 -0.200 0" rpy = "0 0 0"/>		
		<axis xyz= "0 1 0"/>
		<parent link = "chassis"/>
		<child link = "wheel_rl"/>
		<limit effort = "1" velocity = "1" lower = "-3.14" upper = "3.14"/>
    <dynamics damping="1.0" friction="0.3"/>
	</joint>
	<transmission name="chassis_wheel_rl_trans">
    <type>transmission_interface/SimpleTransmission</type>
    <actuator name="chassis_wheel_rl_act">
      <mechanicalReduction>1</mechanicalReduction>
    </actuator>
    <joint name="chassis_wheel_rl">
      <hardwareInterface>hardware_interface/EffortJointInterface</hardwareInterface>
    </joint>
  </transmission>
  <gazebo reference="wheel_rl">
      <mu1 value="200.0"/>
      <mu2 value="100.0"/>
      <kp value="10000000.0" />
      <kd value="1.0" />
      <material>Gazebo/Grey</material>
  </gazebo>

  <link name = "wheel_rl">
		<inertial>
			<mass value = "2"/>
			<origin xyz = "0 0 0" rpy = "1.57 0 0"/>
			<inertia ixx = "0.0022" ixy = "0" ixz = "0" iyy = "0.0022" iyz = "0" izz = "0.0025"/>
		</inertial>
		<collision>
			<origin xyz = "0 0 0" rpy = "1.57 0 0"/>
			<geometry>
					<cylinder  radius = "0.05" length = "0.076"/>
			</geometry>
		</collision>
		<visual>
			<origin xyz = "0 0 0" rpy = "1.57 0 0"/>
			<geometry>
					<cylinder  radius = "0.1" length = "0.076"/>
			</geometry>
		</visual>
	</link>

<!-- join the wheel to the base -->

	<joint name = "chassis__wheel_rr" type = "revolute">
		<origin xyz = "-0.270 0.200 0" rpy = "0 0 0"/>		
		<axis xyz= "0 1 0"/>
		<parent link = "chassis"/>
		<child link = "wheel_rr"/>
		<limit effort = "1" velocity = "1" lower = "-3.14" upper = "3.14"/>
    <dynamics damping="1.0" friction="0.3"/>
	</joint>
  <transmission name="chassis_wheel_rr_trans">
    <type>transmission_interface/SimpleTransmission</type>
    <actuator name="chassis_wheel_rr_act">
      <mechanicalReduction>1</mechanicalReduction>
    </actuator>
    <joint name="chassis_wheel_rr">
      <hardwareInterface>hardware_interface/EffortJointInterface</hardwareInterface>
    </joint>
  </transmission>
  <gazebo reference="wheel_rr">
      <mu1 value="200.0"/>
      <mu2 value="100.0"/>
      <kp value="10000000.0" />
      <kd value="1.0" />
      <material>Gazebo/Grey</material>
  </gazebo>
	
  <link name = "wheel_rr">
		<inertial>
			<mass value = "2"/>
			<origin xyz = "0 0 0" rpy = "1.57 0 0"/>
			<inertia ixx = "0.0022" ixy = "0" ixz = "0" iyy = "0.0022" iyz = "0" izz = "0.0025"/>
		</inertial>
		<collision>
			<origin xyz = "0 0 0" rpy = "1.57 0 0"/>
			<geometry>
					<cylinder  radius = "0.05" length = "0.076"/>
			</geometry>
		</collision>
		<visual>
			<origin xyz = "0 0 0" rpy = "1.57 0 0"/>
			<geometry>
					<cylinder  radius = "0.1" length = "0.076"/>
			</geometry>
		</visual>
	</link>

<!--***************************************** MANIPULATOR ******************************************-->


	<joint name="chassis__base_link" type="fixed">
		<origin xyz="0 0 0.07" rpy="0 0 0"/>
		<axis xyz="0 0 1"/>
    <parent link="chassis"/>
    <child link="base_link"/>
		<limit effort="0" velocity="0" lower="3.14" upper="-3.14"/>
	</joint>
  <transmission name="chassis_base_link_trans">
    <type>transmission_interface/SimpleTransmission</type>
    <actuator name="chassis_base_link_act">
      <mechanicalReduction>1</mechanicalReduction>
    </actuator>
    <joint name="chassis_base_link">
      <hardwareInterface>hardware_interface/EffortJointInterface</hardwareInterface>
    </joint>
  </transmission>
  <gazebo reference="base_link">
      <mu1 value="200.0"/>
      <mu2 value="100.0"/>
      <kp value="10000000.0" />
      <kd value="1.0" />
      <material>Gazebo/Grey</material>
  </gazebo>

  
  
  <link name="base_link">
		<inertial>
			<origin xyz="0 0 0.05" rpy="0 0 0"/>
			<mass value="1.0"/>
			<inertia ixx="0.1458" iyy="0.1458" izz="0.1250" ixy="0" ixz="0" iyz="0"/>
		</inertial>
		<collision>
			<origin xyz="0 0 0.05" rpy="0 0 0"/>
			<geometry>
				<cylinder radius= "0.09" length="0.1"/>
			</geometry>
		</collision>
		<visual>
			<origin xyz="0 0 0.05" rpy="0 0 0"/>
			<geometry> 
				<cylinder radius= "0.09" length="0.1"/>
			</geometry>
			<material name="green">
				<color rgba="0 1 0 0.7"/>
			</material>
		</visual>
	</link>

<!-- base link to link 1-->

  <joint name="base_link__link_1" type="revolute">
		<origin xyz="0 0 0.1" rpy="0 0 0"/>
		<axis xyz="0 0 1"/>
    <parent link="base_link"/>
    <child link="link_1"/>
		<limit effort="0" velocity="0" lower="3.14" upper="-3.14"/>
    <dynamics damping="1.0" friction="0.3"/>
	</joint>
  <transmission name="base_link__link_1_trans">
    <type>transmission_interface/SimpleTransmission</type>
    <actuator name="base_link__link_1_act">
      <mechanicalReduction>1</mechanicalReduction>
    </actuator>
    <joint name="base_link__link_1">
      <hardwareInterface>hardware_interface/EffortJointInterface</hardwareInterface>
    </joint>
  </transmission>
  <gazebo reference="link_1">
      <mu1 value="200.0"/>
      <mu2 value="100.0"/>
      <kp value="10000000.0" />
      <kd value="1.0" />
      <material>Gazebo/Grey</material>
  </gazebo>
	
	
  <link name="link_1">
		<inertial>
			<origin xyz="0 0 0.1" rpy="0 0 0"/>
			<mass value="1.0"/>
			<inertia ixx="0.1458" iyy="0.1458" izz="0.1250" ixy="0" ixz="0" iyz="0"/>
		</inertial>
		<collision>
			<origin xyz="0 0 0.1" rpy="0 0 0"/>
			<geometry>
				<cylinder radius= "0.05" length="0.2"/>
			</geometry>
		</collision>
		<visual>
			<origin xyz="0 0 0.1" rpy="0 0 0"/>
			<geometry> 
				<cylinder radius= "0.05" length="0.2"/>
			</geometry>
			<material name="green">
				<color rgba="0 1 0 0.7"/>
			</material>
		</visual>
	</link>

<!-- link_1 to link_2 -->

	<joint name="link_1__link_2" type="revolute">
		<origin xyz="0 0 0.2" rpy="0 0 0"/>
		<axis xyz="0 1 0"/>
    <parent link="link_1"/>
    <child link="link_2"/>
		<limit effort="0" velocity="0" lower="3.14" upper="-3.14"/>
    <dynamics damping="1.0" friction="0.3"/>
	</joint>
  <transmission name="link_1__link_2_trans">
    <type>transmission_interface/SimpleTransmission</type>
    <actuator name="link_1__link_2_act">
      <mechanicalReduction>1</mechanicalReduction>
    </actuator>
    <joint name="link_1__link_2">
      <hardwareInterface>hardware_interface/EffortJointInterface</hardwareInterface>
    </joint>
  </transmission>
  <gazebo reference="link_2">
      <mu1 value="200.0"/>
      <mu2 value="100.0"/>
      <kp value="10000000.0" />
      <kd value="1.0" />
      <material>Gazebo/Grey</material>
  </gazebo>
	
	
  <link name="link_2">
		<inertial>
			<origin xyz="0 0 0.1" rpy="0 0 0"/>
			<mass value="1.0"/>
			<inertia ixx="0.1458" iyy="0.1458" izz="0.1250" ixy="0" ixz="0" iyz="0"/>
		</inertial>
		<collision>
			<origin xyz="0 0 0.1" rpy="0 0 0"/>
			<geometry>
				<cylinder radius= "0.05" length="0.2"/>
			</geometry>
		</collision>
		<visual>
			<origin xyz="0 0 0.1" rpy="0 0 0"/>
			<geometry> 
				<cylinder radius= "0.05" length="0.2"/>
			</geometry>
			<material name="green">
				<color rgba="0 1 0 0.7"/>
			</material>
		</visual>
	</link>

<!-- link_2 to link_3-->

	<joint name="link_2__link_3" type="revolute">
		<origin xyz="0 0 0.2" rpy="0 0 0"/>
		<axis xyz="0 1 0"/>
    <parent link="link_2"/>
    <child link="link_3"/>
		<limit effort="0" velocity="0" lower="3.14" upper="-3.14"/>
    <dynamics damping="1.0" friction="0.3"/>
	</joint>
  <transmission name="link_2__link_3_trans">
    <type>transmission_interface/SimpleTransmission</type>
    <actuator name="link_2__link_3_act">
      <mechanicalReduction>1</mechanicalReduction>
    </actuator>
    <joint name="link_2__link_3">
      <hardwareInterface>hardware_interface/EffortJointInterface</hardwareInterface>
    </joint>
  </transmission>
  <gazebo reference="link_3">
      <mu1 value="200.0"/>
      <mu2 value="100.0"/>
      <kp value="10000000.0" />
      <kd value="1.0" />
      <material>Gazebo/Grey</material>
  </gazebo>
	
	
  <link name="link_3">
		<inertial>
			<origin xyz="0 0 0.1" rpy="0 0 0"/>
			<mass value="1.0"/>
			<inertia ixx="0.1458" iyy="0.1458" izz="0.1250" ixy="0" ixz="0" iyz="0"/>
		</inertial>
		<collision>
			<origin xyz="0 0 0.1" rpy="0 0 0"/>
			<geometry>
				<cylinder radius= "0.05" length="0.2"/>
			</geometry>
		</collision>
		<visual>
			<origin xyz="0 0 0.1" rpy="0 0 0"/>
			<geometry> 
				<cylinder radius= "0.05" length="0.2"/>
			</geometry>
			<material name="green">
				<color rgba="0 1 0 0.7"/>
			</material>
		</visual>
	</link>

<!-- link_3 to link_4-->

	<joint name="link_3__link_4" type="revolute">
		<origin xyz="0 0 0.2" rpy="0 0 0"/>
		<axis xyz="0 1 0"/>
    <parent link="link_3"/>
    <child link="link_4"/>
		<limit effort="0" velocity="0" lower="3.14" upper="-3.14"/>
    <dynamics damping="1.0" friction="0.3"/>
	</joint>
  <transmission name="link_3__link_4_trans">
    <type>transmission_interface/SimpleTransmission</type>
    <actuator name="link_3__link_4_act">
      <mechanicalReduction>1</mechanicalReduction>
    </actuator>
    <joint name="link_3__link_4">
      <hardwareInterface>hardware_interface/EffortJointInterface</hardwareInterface>
    </joint>
  </transmission>
  <gazebo reference="link_4">
      <mu1 value="200.0"/>
      <mu2 value="100.0"/>
      <kp value="10000000.0" />
      <kd value="1.0" />
      <material>Gazebo/Grey</material>
  </gazebo>
	
	
  <link name="link_4">
		<inertial>
			<origin xyz="0 0 0.1" rpy="0 0 0"/>
			<mass value="1.0"/>
			<inertia ixx="0.1458" iyy="0.1458" izz="0.1250" ixy="0" ixz="0" iyz="0"/>
		</inertial>
		<collision>
			<origin xyz="0 0 0.1" rpy="0 0 0"/>
			<geometry>
				<cylinder radius= "0.05" length="0.2"/>
			</geometry>
		</collision>
		<visual>
			<origin xyz="0 0 0.1" rpy="0 0 0"/>
			<geometry> 
				<cylinder radius= "0.05" length="0.2"/>
			</geometry>
			<material name="green">
				<color rgba="0 1 0 0.7"/>
			</material>
		</visual>
	</link>

<!-- link_4 to end effector -->

	<joint name="link_4__endeff" type="revolute">
		<origin xyz="0 0 0.2" rpy="0 0 0"/>
		<axis xyz="0 0 1"/>
    <parent link="link_4"/>
    <child link="endeff"/>
		<limit effort="0" velocity="0" lower="3.14" upper="-3.14"/>
    <dynamics damping="1.0" friction="0.3"/>
	</joint>
  <transmission name="link_4__endeff_trans">
    <type>transmission_interface/SimpleTransmission</type>
    <actuator name="link_4__endeff_act">
      <mechanicalReduction>1</mechanicalReduction>
    </actuator>
    <joint name="link_4__endeff">
      <hardwareInterface>hardware_interface/EffortJointInterface</hardwareInterface>
    </joint>
  </transmission>
  <gazebo reference="end_eff">
      <mu1 value="200.0"/>
      <mu2 value="100.0"/>
      <kp value="10000000.0" />
      <kd value="1.0" />
      <material>Gazebo/Grey</material>
  </gazebo>
	
	
  <link name="endeff">
		<inertial>
			<origin xyz="0 0 0.05" rpy="0 0 0"/>
			<mass value="1.0"/>
			<inertia ixx="0.1458" iyy="0.1458" izz="0.1250" ixy="0" ixz="0" iyz="0"/>
		</inertial>
		<collision>
			<origin xyz="0 0 0.05" rpy="0 0 0"/>
			<geometry>
				<box size = "0.1 0.1 0.1"/>
			</geometry>
		</collision>
		<visual>
			<origin xyz="0 0 0.05" rpy="0 0 0"/>
			<geometry> 
				<box size = "0.1 0.1 0.1"/>
			</geometry>
			<material name="green">
				<color rgba="0 1 0 0.7"/>
			</material>
		</visual>
	</link>
  
  
  <gazebo>
    <plugin name="gazebo_ros_control" filename="libgazebo_ros_control.so">
      <!--<robotNamespace>/simple_model</robotNamespace>-->
      <legacyModeNS>true</legacyModeNS>
    </plugin>
  </gazebo>
</robot>
